Workbook

Sheet RESUMEN 
A1: Tema que trata la ley | C1: Económico/Fiscal | D1: Económico/Fiscal | E1: Económico/Fiscal | F1: Laboral | G1: Ambiente | H1: Judicial | I1: Acuerdo internacional | J1: Educación | K1: Desregulación | L1: Político | M1: Económico/Fiscal | N1: Acuerdo internacional | O1: Político | P1: Económico/Fiscal | Q1: Económico/Fiscal
C2: Presupuesto 2026 | D2: Ley Inocencia Fiscal | E2: Ley Compromiso Nacional | F2: Ley Modernización Laboral | G2: Ley Glaciares | H2: Ley de Régimen Penal Juvenil | I2: Acuerdo UE - Mercosur | J2: Financiamiento Universitario | K2: Ley Hojarasca | L2: Reforma Electoral | M2: Régimen Zonas Frías | N2: Patentes (PCT) | O2: Ley de Lobby | P2: Super RIGI | Q2: CONCILIACIÓN E/ LA REP. ARG. Y BAINBRIDGE LTD. Y E/ LA REP. ARG. Y EL GRUPO DE ACREED. ENCABEZADO POR ATTESTOR VMF
A3: Diputados | B3: Afirmativo | C3: =COUNTIF(Diputados!I:I,'RESUMEN '!$B$3) | D3: =COUNTIF(Diputados!J:J,'RESUMEN '!$B$3) | E3: =COUNTIF(Diputados!K:K,'RESUMEN '!$B$3) | F3: =COUNTIF(Diputados!L:L,'RESUMEN '!$B$3) | G3: =COUNTIF(Diputados!M:M,'RESUMEN '!$B$3) | H3: =COUNTIF(Diputados!N:N,'RESUMEN '!$B$3) | I3: =COUNTIF(Diputados!O:O,'RESUMEN '!$B$3) | J3: =COUNTIF(Diputados!P:P,'RESUMEN '!$B$3) | K3: =COUNTIF(Diputados!Q:Q,'RESUMEN '!$B$3) | L3: =COUNTIF(Diputados!R:R,'RESUMEN '!$B$3) | M3: =COUNTIF(Diputados!S:S,'RESUMEN '!$B$3) | N3: =COUNTIF(Diputados!T:T,'RESUMEN '!$B$3) | O3: =COUNTIF(Diputados!U:U,'RESUMEN '!$B$3) | P3: =COUNTIF(Diputados!V:V,'RESUMEN '!$B$3) | Q3: =COUNTIF(Diputados!W:W,'RESUMEN '!$B$3)
B4: Abstención | C4: =COUNTIF(Diputados!I:I,'RESUMEN '!$B$4) | D4: =COUNTIF(Diputados!J:J,'RESUMEN '!$B$4) | E4: =COUNTIF(Diputados!K:K,'RESUMEN '!$B$4) | F4: =COUNTIF(Diputados!L:L,'RESUMEN '!$B$4) | G4: =COUNTIF(Diputados!M:M,'RESUMEN '!$B$4) | H4: =COUNTIF(Diputados!N:N,'RESUMEN '!$B$4) | I4: =COUNTIF(Diputados!O:O,'RESUMEN '!$B$4) | J4: =COUNTIF(Diputados!P:P,'RESUMEN '!$B$4) | K4: =COUNTIF(Diputados!Q:Q,'RESUMEN '!$B$4) | L4: =COUNTIF(Diputados!R:R,'RESUMEN '!$B$4) | M4: =COUNTIF(Diputados!S:S,'RESUMEN '!$B$4) | N4: =COUNTIF(Diputados!T:T,'RESUMEN '!$B$4) | O4: =COUNTIF(Diputados!U:U,'RESUMEN '!$B$4) | P4: =COUNTIF(Diputados!V:V,'RESUMEN '!$B$4) | Q4: =COUNTIF(Diputados!W:W,'RESUMEN '!$B$4)
B5: Ausente | C5: =COUNTIF(Diputados!I:I,$B$5) | D5: =COUNTIF(Diputados!J:J,$B$5) | E5: =COUNTIF(Diputados!K:K,$B$5) | F5: =COUNTIF(Diputados!L:L,$B$5) | G5: =COUNTIF(Diputados!M:M,$B$5) | H5: =COUNTIF(Diputados!N:N,$B$5) | I5: =COUNTIF(Diputados!O:O,$B$5) | J5: =COUNTIF(Diputados!P:P,$B$5) | K5: =COUNTIF(Diputados!Q:Q,$B$5) | L5: =COUNTIF(Diputados!R:R,$B$5) | M5: =COUNTIF(Diputados!S:S,$B$5) | N5: =COUNTIF(Diputados!T:T,$B$5) | O5: =COUNTIF(Diputados!U:U,$B$5) | P5: =COUNTIF(Diputados!V:V,$B$5) | Q5: =COUNTIF(Diputados!W:W,$B$5)
B6: Pendiente de incorporación | C6: =COUNTIF(Diputados!I:I,$B$6) | D6: =COUNTIF(Diputados!J:J,$B$6) | E6: =COUNTIF(Diputados!K:K,$B$6) | F6: =COUNTIF(Diputados!L:L,$B$6) | G6: =COUNTIF(Diputados!M:M,$B$6) | H6: =COUNTIF(Diputados!N:N,$B$6) | I6: =COUNTIF(Diputados!O:O,$B$6) | J6: =COUNTIF(Diputados!P:P,$B$6) | K6: =COUNTIF(Diputados!Q:Q,$B$6) | L6: =COUNTIF(Diputados!R:R,$B$6) | M6: =COUNTIF(Diputados!S:S,$B$6) | N6: =COUNTIF(Diputados!T:T,$B$6) | O6: =COUNTIF(Diputados!U:U,$B$6) | P6: =COUNTIF(Diputados!V:V,$B$6) | Q6: =COUNTIF(Diputados!W:W,$B$6)
B7: Presidente | C7: =COUNTIF(Diputados!I:I,$B$7) | D7: =COUNTIF(Diputados!J:J,$B$7) | E7: =COUNTIF(Diputados!K:K,$B$7) | F7: =COUNTIF(Diputados!L:L,$B$7) | G7: =COUNTIF(Diputados!M:M,$B$7) | H7: =COUNTIF(Diputados!N:N,$B$7) | I7: =COUNTIF(Diputados!O:O,$B$7) | J7: =COUNTIF(Diputados!P:P,$B$7) | K7: =COUNTIF(Diputados!Q:Q,$B$7) | L7: =COUNTIF(Diputados!R:R,$B$7) | M7: =COUNTIF(Diputados!S:S,$B$7) | N7: =COUNTIF(Diputados!T:T,$B$7) | O7: =COUNTIF(Diputados!U:U,$B$7) | P7: =COUNTIF(Diputados!V:V,$B$7) | Q7: =COUNTIF(Diputados!W:W,$B$7)
B8: Negativo | C8: =COUNTIF(Diputados!I:I,'RESUMEN '!$B$8) | D8: =COUNTIF(Diputados!J:J,'RESUMEN '!$B$8) | E8: =COUNTIF(Diputados!K:K,'RESUMEN '!$B$8) | F8: =COUNTIF(Diputados!L:L,'RESUMEN '!$B$8) | G8: =COUNTIF(Diputados!M:M,'RESUMEN '!$B$8) | H8: =COUNTIF(Diputados!N:N,'RESUMEN '!$B$8) | I8: =COUNTIF(Diputados!O:O,'RESUMEN '!$B$8) | J8: =COUNTIF(Diputados!P:P,'RESUMEN '!$B$8) | K8: =COUNTIF(Diputados!Q:Q,'RESUMEN '!$B$8) | L8: =COUNTIF(Diputados!R:R,'RESUMEN '!$B$8) | M8: =COUNTIF(Diputados!S:S,'RESUMEN '!$B$8) | N8: =COUNTIF(Diputados!T:T,'RESUMEN '!$B$8) | O8: =COUNTIF(Diputados!U:U,'RESUMEN '!$B$8) | P8: =COUNTIF(Diputados!V:V,'RESUMEN '!$B$8) | Q8: =COUNTIF(Diputados!W:W,'RESUMEN '!$B$8)
A9: Senadores | B9: Afirmativo | C9: =COUNTIF(Senado!R:R,'RESUMEN '!$B$9) | D9: =COUNTIF(Senado!S:S,'RESUMEN '!$B$9) | E9: =COUNTIF(Senado!T:T,'RESUMEN '!$B$9) | F9: =COUNTIF(Senado!U:U,'RESUMEN '!$B$9) | G9: =COUNTIF(Senado!V:V,'RESUMEN '!$B$9) | H9: =COUNTIF(Senado!W:W,'RESUMEN '!$B$9) | I9: =COUNTIF(Senado!X:X,'RESUMEN '!$B$9) | J9: =COUNTIF(Senado!Y:Y,'RESUMEN '!$B$9) | K9: =COUNTIF(Senado!Z:Z,'RESUMEN '!$B$9) | L9: =COUNTIF(Senado!AA:AA,'RESUMEN '!$B$9) | M9: =COUNTIF(Senado!AB:AB,'RESUMEN '!$B$9) | N9: =COUNTIF(Senado!AC:AC,'RESUMEN '!$B$9) | O9: =COUNTIF(Senado!AD:AD,'RESUMEN '!$B$9) | P9: =COUNTIF(Senado!AE:AE,'RESUMEN '!$B$9) | Q9: =COUNTIF(Senado!AF:AF,'RESUMEN '!$B$9)
B10: Abstención | C10: =COUNTIF(Senado!R:R,'RESUMEN '!$B$10) | D10: =COUNTIF(Senado!S:S,'RESUMEN '!$B$10) | E10: =COUNTIF(Senado!T:T,'RESUMEN '!$B$10) | F10: =COUNTIF(Senado!U:U,'RESUMEN '!$B$10) | G10: =COUNTIF(Senado!V:V,'RESUMEN '!$B$10) | H10: =COUNTIF(Senado!W:W,'RESUMEN '!$B$10) | I10: =COUNTIF(Senado!X:X,'RESUMEN '!$B$10) | J10: =COUNTIF(Senado!Y:Y,'RESUMEN '!$B$10) | K10: =COUNTIF(Senado!Z:Z,'RESUMEN '!$B$10) | L10: =COUNTIF(Senado!AA:AA,'RESUMEN '!$B$10) | M10: =COUNTIF(Senado!AB:AB,'RESUMEN '!$B$10) | N10: =COUNTIF(Senado!AC:AC,'RESUMEN '!$B$10) | O10: =COUNTIF(Senado!AD:AD,'RESUMEN '!$B$10) | P10: =COUNTIF(Senado!AE:AE,'RESUMEN '!$B$10) | Q10: =COUNTIF(Senado!AF:AF,'RESUMEN '!$B$10)
B11: Negativo | C11: =COUNTIF(Senado!R:R,'RESUMEN '!$B$11) | D11: =COUNTIF(Senado!S:S,'RESUMEN '!$B$11) | E11: =COUNTIF(Senado!T:T,'RESUMEN '!$B$11) | F11: =COUNTIF(Senado!U:U,'RESUMEN '!$B$11) | G11: =COUNTIF(Senado!V:V,'RESUMEN '!$B$11) | H11: =COUNTIF(Senado!W:W,'RESUMEN '!$B$11) | I11: =COUNTIF(Senado!X:X,'RESUMEN '!$B$11) | J11: =COUNTIF(Senado!Y:Y,'RESUMEN '!$B$11) | K11: =COUNTIF(Senado!Z:Z,'RESUMEN '!$B$11) | L11: =COUNTIF(Senado!AA:AA,'RESUMEN '!$B$11) | M11: =COUNTIF(Senado!AB:AB,'RESUMEN '!$B$11) | N11: =COUNTIF(Senado!AC:AC,'RESUMEN '!$B$11) | O11: =COUNTIF(Senado!AD:AD,'RESUMEN '!$B$11) | P11: =COUNTIF(Senado!AE:AE,'RESUMEN '!$B$11) | Q11: =COUNTIF(Senado!AF:AF,'RESUMEN '!$B$11)
B13: Estado | C13: =IF(AND(C3>(257/2),C9>(72/2)),"Aprobado",IF(OR(AND(C3=0,C9>(72/2)),AND(C9=0,C3>(257/2))),"Media sanción",IF(SUM(C3:C11)=0,"No Tratado","Rechazado"))) | D13: =IF(AND(D3>(257/2),D9>(72/2)),"Aprobado",IF(OR(AND(D3=0,D9>(72/2)),AND(D9=0,D3>(257/2))),"Media sanción",IF(SUM(D3:D11)=0,"No Tratado","Rechazado"))) | E13: =IF(AND(E3>(257/2),E9>(72/2)),"Aprobado",IF(OR(AND(E3=0,E9>(72/2)),AND(E9=0,E3>(257/2))),"Media sanción",IF(SUM(E3:E11)=0,"No Tratado","Rechazado"))) | F13: =IF(AND(F3>(257/2),F9>(72/2)),"Aprobado",IF(OR(AND(F3=0,F9>(72/2)),AND(F9=0,F3>(257/2))),"Media sanción",IF(SUM(F3:F11)=0,"No Tratado","Rechazado"))) | G13: =IF(AND(G3>(257/2),G9>(72/2)),"Aprobado",IF(OR(AND(G3=0,G9>(72/2)),AND(G9=0,G3>(257/2))),"Media sanción",IF(SUM(G3:G11)=0,"No Tratado","Rechazado"))) | H13: =IF(AND(H3>(257/2),H9>(72/2)),"Aprobado",IF(OR(AND(H3=0,H9>(72/2)),AND(H9=0,H3>(257/2))),"Media sanción",IF(SUM(H3:H11)=0,"No Tratado","Rechazado"))) | I13: =IF(AND(I3>(257/2),I9>(72/2)),"Aprobado",IF(OR(AND(I3=0,I9>(72/2)),AND(I9=0,I3>(257/2))),"Media sanción",IF(SUM(I3:I11)=0,"No Tratado","Rechazado"))) | J13: =IF(AND(J3>(257/2),J9>(72/2)),"Aprobado",IF(OR(AND(J3=0,J9>(72/2)),AND(J9=0,J3>(257/2))),"Media sanción",IF(SUM(J3:J11)=0,"No Tratado","Rechazado"))) | ... Q13: =IF(AND(Q3>(257/2),Q9>(72/2)),"Aprobado",IF(OR(AND(Q3=0,Q9>(72/2)),AND(Q9=0,Q3>(257/2))),"Media sanción",IF(SUM(Q3:Q11)=0,"No Tratado","Rechazado")))

Sheet Diputados
A1: Diputado | B1: Apellido | C1: Nombre | D1: Distrito | E1: IniciaMandato | F1: FinalizaMandato | G1: Bloque | H1: Comisión a la que pertenece | I1: Presupuesto 2026 | J1: Ley Inocencia Fiscal | K1: Ley Compromiso Nacional | L1: Ley Modernización Laboral | M1: Ley Glaciares | N1: Ley de Régimen Penal Juvenil | O1: Acuerdo UE - Mercosur | P1: Financiamiento Universitario | Q1: Ley Hojarasca | R1: Reforma Electoral | S1: Régimen Zonas Frías | T1: Patentes (PCT) | U1: Ley de Lobby | V1: Super RIGI | W1: CONCILIACIÓN E/ LA REP. ARG. Y BAINBRIDGE LTD. Y E/ LA REP. ARG. Y EL GRUPO DE ACREED. ENCABEZADO POR ATTESTOR VMF
A2: =_xlfn.CONCAT(B2,,","," ",C2) | B2: Agüero | C2: Guillermo César | D2: CHACO | E2: 46001 | F2: 47461 | G2: UCR - UNIÓN CÍVICA RADICAL | H2: CIENCIA, TECNOLOGIA E INNOVACION PRODUCTIVA | LEGISLACION PENAL | AGRICULTURA Y GANADERIA | INDUSTRIA | ECONOMIAS Y DESARROLLO REGIONAL | ECONOMIA | MERCOSUR | LIBERTAD DE EXPRESION | I2: AFIRMATIVO | J2: AFIRMATIVO | L2: AFIRMATIVO | M2: AFIRMATIVO | N2: AFIRMATIVO | O2: AFIRMATIVO | Q2: AFIRMATIVO | S2: AFIRMATIVO | V2: AFIRMATIVO | W2: AFIRMATIVO
A3: =_xlfn.CONCAT(B3,,","," ",C3) | B3: Aguirre | C3: Hilda | D3: LA RIOJA | E3: 45270 | F3: 46730 | G3: UNIÓN POR LA PATRIA | H3: EDUCACION | CULTURA | DE LAS PERSONAS MAYORES | DISCAPACIDAD | MUJERES Y DIVERSIDAD | I3: NEGATIVO | J3: NEGATIVO | L3: NEGATIVO | M3: NEGATIVO | N3: NEGATIVO | O3: AFIRMATIVO | Q3: NEGATIVO | S3: NEGATIVO | V3: NEGATIVO | W3: NEGATIVO
A4: =_xlfn.CONCAT(B4,,","," ",C4) | B4: Ajmechet | C4: Sabrina | D4: CIUDAD DE BUENOS AIRES | E4: 46001 | F4: 47461 | G4: LA LIBERTAD AVANZA | H4: ASUNTOS CONSTITUCIONALES | RELACIONES EXTERIORES Y CULTO | EDUCACION | CIENCIA, TECNOLOGIA E INNOVACION PRODUCTIVA | LEGISLACION PENAL | ENERGIA Y COMBUSTIBLES | COMUNICACIONES E INFORMATICA | I4: AFIRMATIVO | J4: AFIRMATIVO | L4: AFIRMATIVO | M4: AFIRMATIVO | N4: AFIRMATIVO | O4: AFIRMATIVO | Q4: AFIRMATIVO | S4: AFIRMATIVO | V4: AFIRMATIVO | W4: AFIRMATIVO
A5: =_xlfn.CONCAT(B5,,","," ",C5) | B5: Alí | C5: Ernesto Pipi"" | D5: SAN LUIS | E5: 45322 | F5: 46730 | G5: UNIÓN POR LA PATRIA | H5: ASUNTOS CONSTITUCIONALES | OBRAS PUBLICAS | AGRICULTURA Y GANADERIA | VIVIENDA Y ORDENAMIENTO URBANO | MINERIA | ASUNTOS COOPERATIVOS, MUTUALES Y ORGANIZACIONES NO GUBERNAMENTALES | SEGURIDAD INTERIOR | I5: NEGATIVO | J5: NEGATIVO | L5: NEGATIVO | M5: NEGATIVO | N5: NEGATIVO | O5: AFIRMATIVO | Q5: NEGATIVO | S5: NEGATIVO | V5: NEGATIVO | W5: NEGATIVO
A6: =_xlfn.CONCAT(B6,,","," ",C6) | B6: Almena | C6: Carlos Alberto | D6: SAN LUIS | E6: 46001 | F6: 47461 | G6: LA LIBERTAD AVANZA | H6: CIENCIA, TECNOLOGIA E INNOVACION PRODUCTIVA | FAMILIAS, NIÑEZ Y JUVENTUDES | COMUNICACIONES E INFORMATICA | ASUNTOS MUNICIPALES | PREVENCION DE ADICCIONES Y CONTROL DEL NARCOTRAFICO | POBLACION Y DESARROLLO HUMANO | I6: AFIRMATIVO | J6: AFIRMATIVO | L6: AFIRMATIVO | M6: AFIRMATIVO | N6: AFIRMATIVO | O6: AFIRMATIVO | Q6: AFIRMATIVO | S6: AFIRMATIVO | V6: AFIRMATIVO | W6: AFIRMATIVO
A7: =_xlfn.CONCAT(B7,,","," ",C7) | B7: Almirón | C7: Lisandro | D7: CORRIENTES | E7: 45270 | F7: 46730 | G7: LA LIBERTAD AVANZA | H7: PRESUPUESTO Y HACIENDA | LEGISLACION PENAL | LEGISLACION DEL TRABAJO | OBRAS PUBLICAS | INTERESES MARITIMOS, FLUVIALES, PESQUEROS Y PORTUARIOS | JUICIO POLITICO | RECURSOS NATURALES Y CONSERVACION DEL AMBIENTE HUMANO | ANALISIS Y SEGUIMIENTO DEL CUMPLIMIENTO DE NORMAS TRIBUTARIAS Y PREVISIONALES | LIBERTAD DE EXPRESION | I7: AFIRMATIVO | J7: AFIRMATIVO | L7: AFIRMATIVO | M7: AFIRMATIVO | N7: AFIRMATIVO | O7: AFIRMATIVO | Q7: AFIRMATIVO | S7: AFIRMATIVO | V7: AFIRMATIVO | W7: AFIRMATIVO
A8: =_xlfn.CONCAT(B8,,","," ",C8) | B8: Álvarez | C8: Claudio | D8: SAN LUIS | E8: 46001 | F8: 46730 | G8: INNOVACIÓN FEDERAL | H8: PREVISION Y SEGURIDAD SOCIAL | VIVIENDA Y ORDENAMIENTO URBANO | ANALISIS Y SEGUIMIENTO DEL CUMPLIMIENTO DE NORMAS TRIBUTARIAS Y PREVISIONALES | SEGURIDAD INTERIOR | I8: AFIRMATIVO | J8: AFIRMATIVO | L8: NEGATIVO | M8: AFIRMATIVO | N8: AFIRMATIVO | O8: AFIRMATIVO | Q8: AFIRMATIVO | S8: NEGATIVO | V8: AFIRMATIVO | W8: AFIRMATIVO
A9: =_xlfn.CONCAT(B9,,","," ",C9) | B9: Andino | C9: Cristian | D9: SAN JUAN | E9: 46001 | F9: 47461 | G9: UNIÓN POR LA PATRIA | H9: PRESUPUESTO Y HACIENDA | ECONOMIAS Y DESARROLLO REGIONAL | ASUNTOS MUNICIPALES | MINERIA | ANALISIS Y SEGUIMIENTO DEL CUMPLIMIENTO DE NORMAS TRIBUTARIAS Y PREVISIONALES | DISCAPACIDAD | I9: NEGATIVO | J9: NEGATIVO | L9: NEGATIVO | M9: AFIRMATIVO | N9: NEGATIVO | O9: AFIRMATIVO | Q9: NEGATIVO | S9: NEGATIVO | V9: NEGATIVO | W9: NEGATIVO
A10: =_xlfn.CONCAT(B10,,","," ",C10) | B10: Andrade | C10: Javier | D10: CIUDAD DE BUENOS AIRES | E10: 46001 | F10: 46730 | G10: UNIÓN POR LA PATRIA | H10: RELACIONES EXTERIORES Y CULTO | VIVIENDA Y ORDENAMIENTO URBANO | POBLACION Y DESARROLLO HUMANO | DEPORTES | DERECHOS HUMANOS Y GARANTIAS | MERCOSUR | I10: NEGATIVO | J10: NEGATIVO | L10: NEGATIVO | M10: NEGATIVO | N10: NEGATIVO | O10: NEGATIVO | Q10: NEGATIVO | S10: NEGATIVO | V10: NEGATIVO | W10: NEGATIVO
A11: =_xlfn.CONCAT(B11,,","," ",C11) | B11: Andreussi | C11: Barbara | D11: JUJUY | E11: 46001 | F11: 47461 | G11: LA LIBERTAD AVANZA | H11: CULTURA | FAMILIAS, NIÑEZ Y JUVENTUDES | DE LAS PERSONAS MAYORES | ECONOMIAS Y DESARROLLO REGIONAL | MINERIA | PREVENCION DE ADICCIONES Y CONTROL DEL NARCOTRAFICO | POBLACION Y DESARROLLO HUMANO | DISCAPACIDAD | I11: AFIRMATIVO | J11: AFIRMATIVO | L11: AFIRMATIVO | M11: AFIRMATIVO | N11: AFIRMATIVO | O11: AFIRMATIVO | Q11: AFIRMATIVO | S11: AFIRMATIVO | V11: AFIRMATIVO | W11: AFIRMATIVO
A12: =_xlfn.CONCAT(B12,,","," ",C12) | B12: Ansaloni | C12: Pablo | D12: BUENOS AIRES | E12: 45270 | F12: 46730 | G12: LA LIBERTAD AVANZA | H12: PREVISION Y SEGURIDAD SOCIAL | ACCION SOCIAL Y SALUD PUBLICA | LEGISLACION DEL TRABAJO | AGRICULTURA Y GANADERIA | ECONOMIAS Y DESARROLLO REGIONAL | RECURSOS NATURALES Y CONSERVACION DEL AMBIENTE HUMANO | DEPORTES | PEQUEÑAS Y MEDIANAS EMPRESAS | I12: AFIRMATIVO | J12: AFIRMATIVO | L12: AFIRMATIVO | M12: AFIRMATIVO | N12: AFIRMATIVO | O12: AFIRMATIVO | Q12: AFIRMATIVO | S12: AFIRMATIVO | V12: AFIRMATIVO | W12: AFIRMATIVO
A13: =_xlfn.CONCAT(B13,,","," ",C13) | B13: Arabia | C13: Damián | D13: CIUDAD DE BUENOS AIRES | E13: 45270 | F13: 46730 | G13: LA LIBERTAD AVANZA | H13: RELACIONES EXTERIORES Y CULTO | CIENCIA, TECNOLOGIA E INNOVACION PRODUCTIVA | DEFENSA NACIONAL | FINANZAS | COMUNICACIONES E INFORMATICA | ECONOMIAS Y DESARROLLO REGIONAL | TURISMO | MERCOSUR | SEGURIDAD INTERIOR | I13: AFIRMATIVO | J13: AFIRMATIVO | L13: AFIRMATIVO | M13: AFIRMATIVO | N13: AFIRMATIVO | O13: AFIRMATIVO | Q13: AFIRMATIVO | S13: AFIRMATIVO | V13: AFIRMATIVO | W13: AFIRMATIVO
... A258: =_xlfn.CONCAT(B258,,","," ",C258) | B258: Zulli | C258: Christian Alejandro | D258: CORRIENTES | E258: 45270 | F258: 46730 | G258: UNIÓN POR LA PATRIA | H258: PREVISION Y SEGURIDAD SOCIAL | OBRAS PUBLICAS | AGRICULTURA Y GANADERIA | ANALISIS Y SEGUIMIENTO DEL CUMPLIMIENTO DE NORMAS TRIBUTARIAS Y PREVISIONALES | MERCOSUR | I258: NEGATIVO | J258: NEGATIVO | L258: NEGATIVO | M258: NEGATIVO | N258: NEGATIVO | O258: ABSTENCIÓN | Q258: NEGATIVO | S258: NEGATIVO | V258: NEGATIVO | W258: NEGATIVO

Sheet Senado
A1: Senador | B1: NOMBRE | C1: APELLIDO | D1: Bloque | E1: PROVINCIA | F1: PARTIDO O ALIANZA POR EL QUE INGRESÓ | G1: DESIGNACIÓN LEGAL | H1: CESE LEGAL | I1: DESIGNACIÓN REAL | J1: CESE REAL | K1: EMAIL | L1: TELEFONO | M1: FACEBOOK | N1: TWITTER | O1: INSTAGRAM | P1: YOUTUBE | Q1: Comisión a la que pertenece | R1: Presupuesto 2026 | S1: Ley Inocencia Fiscal | T1: Ley Compromiso Nacional | U1: Ley Modernización Laboral | V1: Ley Glaciares | W1: Ley de Régimen Penal Juvenil | X1: Acuerdo UE - Mercosur | Y1: Financiamiento Universitario | Z1: Ley Hojarasca | AA1: Reforma Electoral | AB1: Régimen Zonas Frías | AC1: Patentes (PCT) | AD1: Ley de Lobby | AE1: Super RIGI | AF1: CONCILIACIÓN E/ LA REP. ARG. Y BAINBRIDGE LTD. Y E/ LA REP. ARG. Y EL GRUPO DE ACREED. ENCABEZADO POR ATTESTOR VMF
A2: =_xlfn.CONCAT(C2," ",B2) | B2: MAXIMILIANO | C2: ABAD | D2: UCR - UNIÓN CÍVICA RADICAL | E2: BUENOS AIRES | F2: ALIANZA UNIÓN POR LA PATRIA | G2: 2023-12-10 | H2: 2029-12-09 | I2: 2023-12-10 | J2: Sin Datos | K2: fernando.salino@senado.gob.ar | L2: 1524 | M2: https://www.facebook.com/fersalino | N2: https://twitter.com/Fernando_Salino | O2: https://www.instagram.com/fernando_salino1 | Q2: De Acuerdos | De Asuntos Administrativos y Municipales | De Coparticipación Federal de Impuestos | De Deporte | De Derechos y Garantías | De Legislación General | De Relaciones Exteriores y Culto | R2: Negativo | S2: Afirmativo | U2: Afirmativo | V2: NEGATIVO | W2: Afirmativo | X2: AFIRMATIVO | AF2: AFIRMATIVO
A3: =_xlfn.CONCAT(C3," ",B3) | B3: BARTOLOMÉ ESTEBAN | C3: ABDALA | D3: LA LIBERTAD AVANZA | E3: SAN LUIS | F3: ALIANZA UNIÓN POR LA PATRIA | G3: 2023-12-10 | H3: 2029-12-09 | I3: 2023-12-10 | J3: Sin Datos | K3: alicia.kirchner@senado.gob.ar | L3: 1389 / 1390 | Q3: Bicameral Permanente de Fiscalización de los Órganos y Actividades de Seguridad Interior (Ley 24.059 y Sus Modificatorias Leyes 24.194 y 25.520) | De Coparticipación Federal de Impuestos | De Defensa Nacional | De Deporte | De Economía Nacional e Inversión | De Industria y Comercio | De Legislación General | De Presupuesto y Hacienda | R3: Afirmativo | S3: Afirmativo | U3: Afirmativo | V3: AFIRMATIVO | W3: Afirmativo | X3: AFIRMATIVO | AF3: AFIRMATIVO
A4: =_xlfn.CONCAT(C4," ",B4) | B4: ROMINA MARÍA | C4: ALMEIDA | D4: LA LIBERTAD AVANZA | E4: ENTRE RÍOS | F4: JUNTOS POR EL CAMBIO | G4: 2021-12-10 | H4: 2027-12-09 | I4: 2021-12-10 | J4: Sin Datos | K4: daniel.kroneberger@senado.gob.ar | L4: 1321 / 1324 | M4: https://www.facebook.com/kronebergerdaniel | N4: https://twitter.com/Dkroneberger | O4: https://www.instagram.com/kroneberger_daniel/?hl=en | Q4: Bicameral Permanente de la Defensoría del Pueblo | Bicameral Permanente de Promoción y Seguimiento de la Comunicación Audiovisual, las Tecnologías de las Telecomunicaciones y la Digitalización (Ley 26.522,Y Sus Modificatorias 27.078 y Dnu 267/15) | Banca de la Mujer | De Ambiente y Desarrollo Sustentable | De Ciencia y Tecnología | De Economías Regionales, Economía Social, Micro, Pequeña y Mediana Empresa | De Educación y Cultura | De Industria y Comercio | De Infraestructura, Vivienda y Transporte | De Turismo | R4: Afirmativo | S4: Afirmativo | U4: Afirmativo | V4: AFIRMATIVO | W4: Afirmativo | X4: AFIRMATIVO | AF4: AFIRMATIVO
A5: =_xlfn.CONCAT(C5," ",B5) | B5: CARMEN | C5: ÁLVAREZ RIVERO | D5: LA LIBERTAD AVANZA | E5: CÓRDOBA | F5: FRENTE DE TODOS | G5: 2021-12-10 | H5: 2027-12-09 | I5: 2021-12-10 | J5: Sin Datos | K5: marcelo.lewandowski@senado.gob.ar | L5: 1215 | Q5: Bicameral Permanente del Defensor de los Derechos de Niñas, Niños y Adolescentes (Ley 26.061) | Banca de la Mujer | De Agricultura, Ganadería y Pesca | De Coparticipación Federal de Impuestos | De Economía Nacional e Inversión | De Educación y Cultura | De Población y Desarrollo Humano | De Presupuesto y Hacienda | De Salud | R5: Afirmativo | S5: Afirmativo | U5: Afirmativo | V5: AFIRMATIVO | W5: Afirmativo | X5: AFIRMATIVO | AF5: AFIRMATIVO
A6: =_xlfn.CONCAT(C6," ",B6) | B6: GUILLERMO EDUARDO | C6: ANDRADA | D6: CONVICCIÓN FEDERAL | E6: CATAMARCA | F6: JUNTOS POR EL CAMBIO | G6: 2023-12-10 | H6: 2029-12-09 | I6: 2023-12-10 | J6: Sin Datos | K6: maximiliano.abad@senado.gob.ar | L6: 1045 / 1046 | M6: https://www.facebook.com/maxiabad?mibextid=9R9pXO | N6: https://x.com/maxiabad?s=11 | O6: https://www.instagram.com/maxi.abad?igsh=MXc2YzF3YWduc3hneA== | Q6: Bicameral Permanente de Promoción y Seguimiento de la Comunicación Audiovisual, las Tecnologías de las Telecomunicaciones y la Digitalización (Ley 26.522,Y Sus Modificatorias 27.078 y Dnu 267/15) | Bicameral Permanente Parlamentaria Mixta Revisora de Cuentas | De Ciencia y Tecnología | De Economía Nacional e Inversión | De Economías Regionales, Economía Social, Micro, Pequeña y Mediana Empresa | De Presupuesto y Hacienda | De Relaciones Exteriores y Culto | De Salud | De Sistemas, Medios de Comunicación y Libertad de Expresión | R6: Afirmativo | S6: Abstención | U6: Negativo | V6: AFIRMATIVO | W6: Negativo | X6: AFIRMATIVO | AF6: AFIRMATIVO
A7: =_xlfn.CONCAT(C7," ",B7) | B7: CARLOS OMAR | C7: ARCE | D7: ENCUENTRO MISIONERO | E7: MISIONES | F7: ALIANZA LA LIBERTAD AVANZA | G7: 2025-12-10 | H7: 2031-12-09 | I7: 2025-12-10 | J7: Sin Datos | K7: joaquin.benegas@senado.gob.ar | Q7: De Acuerdos | De Deporte | De Infraestructura, Vivienda y Transporte | De Justicia y Asuntos Penales | De Salud | De Turismo | R7: Afirmativo | S7: Afirmativo | U7: Afirmativo | V7: AFIRMATIVO | W7: Afirmativo | X7: AFIRMATIVO | AF7: AFIRMATIVO
A8: =_xlfn.CONCAT(C8," ",B8) | B8: IVANNA MARCELA | C8: ARRASCAETA | D8: LA LIBERTAD AVANZA | E8: SAN LUIS | F8: FRENTE DE TODOS | G8: 2021-12-10 | H8: 2027-12-09 | I8: 2021-12-10 | J8: Sin Datos | K8: carlos.linares@senado.gob.ar | L8: 1373 / 1371 / 1368 | M8: https://www.facebook.com/LinaresCarlosCR | N8: https://twitter.com/LinaresCarlosCR | O8: https://www.instagram.com/carloslinarescr/ | Q8: Banca de la Mujer | De Ambiente y Desarrollo Sustentable | De Coparticipación Federal de Impuestos | De Deporte | De Economía Nacional e Inversión | De Educación y Cultura | De Relaciones Exteriores y Culto | De Salud | R8: Afirmativo | S8: Afirmativo | U8: Afirmativo | V8: AFIRMATIVO | W8: Afirmativo | X8: AFIRMATIVO | AF8: AFIRMATIVO
A9: =_xlfn.CONCAT(C9," ",B9) | B9: EZEQUIEL | C9: ATAUCHE | D9: LA LIBERTAD AVANZA | E9: JUJUY | F9: ALIANZA FRENTE DE TODOS | G9: 2025-12-10 | H9: 2031-12-09 | I9: 2025-12-10 | J9: Sin Datos | K9: cristina.lopez@senado.gob.ar | Q9: Bicameral Permanente Parlamentaria Mixta Revisora de Cuentas | De Ambiente y Desarrollo Sustentable | De Asuntos Administrativos y Municipales | De Ciencia y Tecnología | De Derechos y Garantías | De Minería, Energía y Combustibles | R9: Afirmativo | S9: Afirmativo | U9: Afirmativo | V9: AFIRMATIVO | W9: Afirmativo | X9: AFIRMATIVO | AF9: AFIRMATIVO
A10: =_xlfn.CONCAT(C10," ",B10) | B10: BEATRIZ LUISA | C10: AVILA | D10: INDEPENDENCIA | E10: TUCUMÁN | F10: ALIANZA LA LIBERTAD AVANZA | G10: 2025-12-10 | H10: 2031-12-09 | I10: 2025-12-10 | J10: Sin Datos | K10: patricia.bullrich@senado.gob.ar | Q10: Bicameral Permanente de la Defensoría del Pueblo | Banca de la Mujer | De Asuntos Constitucionales | De Deporte | De Economías Regionales, Economía Social, Micro, Pequeña y Mediana Empresa | De Educación y Cultura | De Justicia y Asuntos Penales | De Presupuesto y Hacienda | R10: Afirmativo | S10: Afirmativo | U10: Afirmativo | V10: AFIRMATIVO | W10: Afirmativo | X10: AFIRMATIVO | AF10: AFIRMATIVO
A11: =_xlfn.CONCAT(C11," ",B11) | B11: ADÁN HUMBERTO | C11: BAHL | D11: JUSTICIALISTA | E11: ENTRE RÍOS | F11: FUERZA PATRIA | G11: 2025-12-10 | H11: 2031-12-09 | I11: 2025-12-10 | J11: Sin Datos | K11: jorge.capitanich@senado.gob.ar | Q11: Bicameral de Reforma del Estado y del Seguimiento de las Privatizaciones (Ley 23.696) | Bicameral Permanente de Fiscalización de los Órganos y Actividades de Seguridad Interior (Ley 24.059 y Sus Modificatorias Leyes 24.194 y 25.520) | Bicameral Permanente de Seguimiento y Control del Ministerio Público de la Nación (Ley 24.946 y Sus Modificatorias Ley 27.148 y 27.149) | De Economía Nacional e Inversión | De Economías Regionales, Economía Social, Micro, Pequeña y Mediana Empresa | De Relaciones Exteriores y Culto | De Seguridad Interior y Narcotráfico | R11: Negativo | S11: Negativo | U11: Negativo | V11: NEGATIVO | W11: Negativo | X11: AFIRMATIVO | AF11: AUSENTE
A12: =_xlfn.CONCAT(C12," ",B12) | B12: VILMA FACUNDA | C12: BEDIA | D12: LA LIBERTAD AVANZA | E12: JUJUY | F12: ALIANZA UNIÓN POR LA PATRIA | G12: 2023-12-10 | H12: 2029-12-09 | I12: 2023-12-10 | J12: Sin Datos | K12: florencia.lopez@senado.gob.ar | L12: 1330/1331/3529 / 3530 | M12: https://www.facebook.com/share/19thWpNnL2/?mibextid=wwXIfr | N12: https://twitter.com/florelop?s=21&t=Lw6vKRLT-9lZyXSvaCKo8Q | O12: https://www.instagram.com/florelop?igsh=MW5vdndpcjB5NnN6Mw== | Q12: Bicameral Permanente del Defensor de los Derechos de Niñas, Niños y Adolescentes (Ley 26.061) | Banca de la Mujer | De Ambiente y Desarrollo Sustentable | De Asuntos Administrativos y Municipales | De Ciencia y Tecnología | De Economías Regionales, Economía Social, Micro, Pequeña y Mediana Empresa | De Educación y Cultura | De Sistemas, Medios de Comunicación y Libertad de Expresión | De Turismo | R12: Afirmativo | S12: Afirmativo | U12: Afirmativo | V12: AFIRMATIVO | W12: Afirmativo | X12: AFIRMATIVO | AF12: AFIRMATIVO
A13: =_xlfn.CONCAT(C13," ",B13) | B13: JOAQUÍN ALBERTO | C13: BENEGAS LYNCH | D13: LA LIBERTAD AVANZA | E13: ENTRE RÍOS | F13: JUNTOS POR EL CAMBIO | G13: 2021-12-10 | H13: 2027-12-09 | I13: 2021-12-10 | J13: Sin Datos | K13: carolina.losada@senado.gob.ar | L13: 5421 / 1426 / 1423 | M13: https://www.facebook.com/carolosada | N13: https://twitter.com/carolinalosada | O13: https://www.instagram.com/carolosada | P13: https://www.youtube.com/@carolinalosadasenadora?si=biSelDnRlatwDG_o | Q13: Bicameral de Reforma del Estado y del Seguimiento de las Privatizaciones (Ley 23.696) | De Agricultura, Ganadería y Pesca | De Economías Regionales, Economía Social, Micro, Pequeña y Mediana Empresa | De Industria y Comercio | De Infraestructura, Vivienda y Transporte | De Población y Desarrollo Humano | De Trabajo y Previsión Social | R13: Afirmativo | S13: Afirmativo | U13: Afirmativo | V13: AFIRMATIVO | W13: Afirmativo | X13: AFIRMATIVO | AF13: AFIRMATIVO
A14: =_xlfn.CONCAT(C14," ",B14) | B14: DANIEL PABLO | C14: BENSUSÁN | D14: JUSTICIALISTA | E14: LA PAMPA | F14: ALIANZA POR SANTA CRUZ | G14: 2023-12-10 | H14: 2029-12-09 | I14: 2023-12-10 | J14: Sin Datos | K14: jose.carambia@senado.gob.ar | L14: 3408 | Q14: Bicameral de Control de los Fondos de la Seguridad Social (Ley 26.425) | Bicameral Permanente de Fiscalización de los Órganos y Actividades de Seguridad Interior (Ley 24.059 y Sus Modificatorias Leyes 24.194 y 25.520) | De Coparticipación Federal de Impuestos | De Industria y Comercio | De Infraestructura, Vivienda y Transporte | De Legislación General | De Población y Desarrollo Humano | R14: Negativo | S14: Negativo | U14: Negativo | V14: NEGATIVO | W14: Negativo | X14: AFIRMATIVO | AF14: NEGATIVO
A15: =_xlfn.CONCAT(C15," ",B15) | B15: PATRICIA | C15: BULLRICH | D15: LA LIBERTAD AVANZA | E15: CIUDAD AUTÓNOMA DE BUENOS AIRES | F15: ALIANZA FRENTE DE TODOS | G15: 2023-12-09 | H15: 2027-12-09 | I15: 2023-12-09 | J15: Sin Datos | K15: juan.manzur@senado.gob.ar | L15: 1354/1380 | M15: https://www.facebook.com/JuanManzurOficial/ | N15: https://twitter.com/JuanManzurOK | O15: https://www.instagram.com/juanluismanzur/ | P15: https://www.youtube.com/@JuanManzurOK | Q15: Banca de la Mujer | De Acuerdos | De Asuntos Constitucionales | De Justicia y Asuntos Penales | De Legislación General | De Presupuesto y Hacienda | De Sistemas, Medios de Comunicación y Libertad de Expresión | R15: Afirmativo | S15: Afirmativo | U15: Afirmativo | V15: AFIRMATIVO | W15: Afirmativo | X15: AFIRMATIVO | AF15: AFIRMATIVO
A16: =_xlfn.CONCAT(C16," ",B16) | B16: JORGE MILTON | C16: CAPITANICH | D16: JUSTICIALISTA | E16: CHACO | F16: ALIANZA LA LIBERTAD AVANZA | G16: 2025-12-10 | H16: 2031-12-09 | I16: 2025-12-10 | J16: Sin Datos | K16: mario.cervi@senado.gob.ar | Q16: De Defensa Nacional | De Relaciones Exteriores y Culto | R16: Negativo | S16: Negativo | U16: Negativo | V16: NEGATIVO | W16: Negativo | X16: AFIRMATIVO | AF16: NEGATIVO
A17: =_xlfn.CONCAT(C17," ",B17) | B17: JOSÉ MARÍA | C17: CARAMBIA | D17: MOVERE SANTA CRUZ | E17: SANTA CRUZ | F17: ALIANZA LA LIBERTAD AVANZA | G17: 2023-12-10 | H17: 2029-12-09 | I17: 2023-12-10 | J17: Sin Datos | K17: francisco.paoltroni@senado.gob.ar | L17: 3872 | Q17: De Infraestructura, Vivienda y Transporte | De Legislación General | De Minería, Energía y Combustibles | De Trabajo y Previsión Social | R17: Afirmativo | S17: Afirmativo | U17: Abstención | V17: NEGATIVO | W17: Afirmativo | X17: AFIRMATIVO | AF17: NEGATIVO
A18: =_xlfn.CONCAT(C18," ",B18) | B18: MARIO PABLO | C18: CERVI | D18: LA LIBERTAD AVANZA | E18: NEUQUÉN | F18: FUERZA PATRIA | G18: 2025-12-10 | H18: 2031-12-09 | I18: 2025-12-10 | J18: Sin Datos | K18: ana.marks@senado.gob.ar | Q18: Bicameral de Control de los Fondos de la Seguridad Social (Ley 26.425) | Bicameral de Reforma del Estado y del Seguimiento de las Privatizaciones (Ley 23.696) | De Agricultura, Ganadería y Pesca | De Derechos y Garantías | De Industria y Comercio | De Minería, Energía y Combustibles | De Salud | De Sistemas, Medios de Comunicación y Libertad de Expresión | R18: Afirmativo | S18: Afirmativo | U18: Afirmativo | V18: AFIRMATIVO | W18: Afirmativo | X18: AFIRMATIVO | AF18: AFIRMATIVO
A19: =_xlfn.CONCAT(C19," ",B19) | B19: LUCÍA BENIGNA | C19: CORPACCI | D19: JUSTICIALISTA | E19: CATAMARCA | F19: FRENTE DE TODOS | G19: 2021-12-10 | H19: 2027-12-09 | I19: 2021-12-10 | J19: Sin Datos | K19: lucia.corpacci@senado.gob.ar | L19: 1435 / 1403 | Q19: Banca de la Mujer | De Coparticipación Federal de Impuestos | De Defensa Nacional | De Derechos y Garantías | De Economías Regionales, Economía Social, Micro, Pequeña y Mediana Empresa | De Industria y Comercio | De Salud | R19: Negativo | S19: Negativo | U19: Negativo | V19: AFIRMATIVO | W19: Negativo | X19: AFIRMATIVO | AF19: NEGATIVO
A20: =_xlfn.CONCAT(C20," ",B20) | B20: JULIETA | C20: CORROZA | D20: LA NEUQUINIDAD | E20: NEUQUÉN | F20: ALIANZA LA LIBERTAD AVANZA | G20: 2023-12-10 | H20: 2029-12-09 | I20: 2023-12-10 | J20: Sin Datos | K20: juan.pagotto@senado.gob.ar | L20: 1008 | Q20: Bicameral Permanente de Seguimiento y Control del Ministerio Público de la Nación (Ley 24.946 y Sus Modificatorias Ley 27.148 y 27.149) | Banca de la Mujer | De Economía Nacional e Inversión | De Infraestructura, Vivienda y Transporte | De Minería, Energía y Combustibles | De Seguridad Interior y Narcotráfico | De Turismo | R20: Abstención | S20: Afirmativo | U20: Afirmativo | V20: ABSTENCIÓN | W20: Afirmativo | X20: AFIRMATIVO | AF20: AUSENTE
A21: =_xlfn.CONCAT(C21," ",B21) | B21: AGUSTÍN PEDRO | C21: COTO | D21: LA LIBERTAD AVANZA | E21: TIERRA DEL FUEGO, ANTÁRTIDA E ISLAS DEL ATLÁNTICO SUR | F21: ALIANZA LA LIBERTAD AVANZA | G21: 2025-12-10 | H21: 2031-12-09 | I21: 2025-12-10 | J21: Sin Datos | K21: nadia.marquez@senado.gob.ar | Q21: De Acuerdos | De Asuntos Constitucionales | De Industria y Comercio | De Legislación General | De Minería, Energía y Combustibles | De Seguridad Interior y Narcotráfico | De Sistemas, Medios de Comunicación y Libertad de Expresión | R21: Afirmativo | S21: Afirmativo | U21: Afirmativo | V21: AFIRMATIVO | W21: Afirmativo | X21: AFIRMATIVO | AF21: AFIRMATIVO
A22: =_xlfn.CONCAT(C22," ",B22) | B22: ANDREA MARCELA | C22: CRISTINA | D22: FRENTE PRO | E22: CHUBUT | F22: JUNTOS POR EL CAMBIO | G22: 2021-12-10 | H22: 2027-12-09 | I22: 2021-12-10 | J22: Sin Datos | K22: beatriz.avila@senado.gob.ar | L22: 3508 / 3309 / 1086 | M22: http://www.facebook.com/beatrizavilaok | N22: http://www.twitter.com/beatriz_avilaok | O22: http://www.instagram.com/beatrizavilaok | P22: http://www.beatrizavila.com.ar/ | Q22: Bicameral Permanente del Defensor de los Derechos de Niñas, Niños y Adolescentes (Ley 26.061) | Banca de la Mujer | De Coparticipación Federal de Impuestos | De Economía Nacional e Inversión | De Economías Regionales, Economía Social, Micro, Pequeña y Mediana Empresa | De Minería, Energía y Combustibles | De Presupuesto y Hacienda | R22: Afirmativo | S22: Afirmativo | U22: Afirmativo | V22: NEGATIVO | W22: Afirmativo | X22: AFIRMATIVO | AF22: AUSENTE
A23: =_xlfn.CONCAT(C23," ",B23) | B23: EDUARDO ENRIQUE | C23: DE PEDRO | D23: JUSTICIALISTA | E23: BUENOS AIRES | F23: LA NEUQUINIDAD | G23: 2025-12-10 | H23: 2031-12-09 | I23: 2025-12-10 | J23: Sin Datos | K23: julieta.corroza@senado.gob.ar | Q23: De Asuntos Administrativos y Municipales | De Ciencia y Tecnología | De Coparticipación Federal de Impuestos | De Deporte | De Educación y Cultura | De Industria y Comercio | R23: Negativo | S23: Negativo | U23: Negativo | V23: NEGATIVO | W23: Negativo | X23: NEGATIVO | AF23: NEGATIVO
A24: =_xlfn.CONCAT(C24," ",B24) | B24: JULIANA | C24: DI TULLIO | D24: JUSTICIALISTA | E24: BUENOS AIRES | F24: ALIANZA LA LIBERTAD AVANZA | G24: 2025-12-10 | H24: 2031-12-09 | I24: 2025-12-10 | J24: Sin Datos | K24: agustin.coto@senado.gob.ar | Q24: Bicameral Permanente de Promoción y Seguimiento de la Comunicación Audiovisual, las Tecnologías de las Telecomunicaciones y la Digitalización (Ley 26.522,Y Sus Modificatorias 27.078 y Dnu 267/15) | Banca de la Mujer | De Economía Nacional e Inversión | De Relaciones Exteriores y Culto | De Turismo | R24: Negativo | S24: Negativo | U24: Negativo | V24: NEGATIVO | W24: Negativo | X24: NEGATIVO | AF24: AUSENTE
A25: =_xlfn.CONCAT(C25," ",B25) | B25: CARLOS MAURICIO | C25: ESPÍNOLA | D25: PROVINCIAS UNIDAS | E25: CORRIENTES | F25: FRENTE RENOVADOR DE LA CONCORDIA-INNOVACIÓN FEDERAL | G25: 2023-12-10 | H25: 2029-12-09 | I25: 2023-12-10 | J25: Sin Datos | K25: sonia.rojas@senado.gob.ar | L25: 3456 / 3457 | M25: https://www.facebook.com/100087662746565 | N25: https://x.com/decutrojas | O25: https://www.instagram.com/soniarojasdecut | Q25: Bicameral de Reforma del Estado y del Seguimiento de las Privatizaciones (Ley 23.696) | Bicameral Permanente de Promoción y Seguimiento de la Comunicación Audiovisual, las Tecnologías de las Telecomunicaciones y la Digitalización (Ley 26.522,Y Sus Modificatorias 27.078 y Dnu 267/15) | De Acuerdos | De Agricultura, Ganadería y Pesca | De Legislación General | De Presupuesto y Hacienda | De Seguridad Interior y Narcotráfico | R25: Afirmativo | S25: Afirmativo | U25: Afirmativo | V25: AFIRMATIVO | W25: Afirmativo | X25: AFIRMATIVO | AF25: AFIRMATIVO
A26: =_xlfn.CONCAT(C26," ",B26) | B26: FLAVIO SERGIO | C26: FAMA | D26: UCR - UNIÓN CÍVICA RADICAL | E26: CATAMARCA | F26: ALIANZA LA LIBERTAD AVANZA | G26: 2025-12-10 | H26: 2031-12-09 | I26: 2025-12-10 | J26: Sin Datos | K26: silvana.schneider@senado.gob.ar | Q26: Bicameral Permanente Parlamentaria Mixta Revisora de Cuentas | De Asuntos Constitucionales | De Ciencia y Tecnología | De Derechos y Garantías | De Educación y Cultura | De Justicia y Asuntos Penales | De Minería, Energía y Combustibles | De Sistemas, Medios de Comunicación y Libertad de Expresión | De Turismo | R26: Negativo | S26: Afirmativo | U26: Afirmativo | V26: AFIRMATIVO | W26: Afirmativo | X26: AFIRMATIVO | AF26: AFIRMATIVO
A27: =_xlfn.CONCAT(C27," ",B27) | B27: ANABEL | C27: FERNÁNDEZ SAGASTI | D27: JUSTICIALISTA | E27: MENDOZA | F27: JUNTOS POR EL CAMBIO CHUBUT | G27: 2023-12-10 | H27: 2027-12-09 | I27: 2023-12-10 | J27: Sin Datos | K27: andrea.cristina@senado.gob.ar | L27: 3453 | M27: https://www.facebook.com/AndreaCristina.Chubut?mibextid=LQQJ4d | N27: https://x.com/andycristina07?s=11 | O27: https://www.instagram.com/andreacristina.chubut?igsh=Y2hzbzE3MWEyaGxl | Q27: Banca de la Mujer | De Deporte | De Derechos y Garantías | De Educación y Cultura | De Relaciones Exteriores y Culto | De Salud | De Seguridad Interior y Narcotráfico | R27: Negativo | S27: Negativo | U27: Negativo | V27: NEGATIVO | W27: Negativo | X27: AFIRMATIVO | AF27: NEGATIVO
A28: =_xlfn.CONCAT(C28," ",B28) | B28: FULLONE | C28: ENZO PAOLO | D28: LA LIBERTAD AVANZA | E28: RÍO NEGRO | F28: ALIANZA LA LIBERTAD AVANZA | G28: 2025-12-26 | H28: 2031-12-09 | I28: 2025-12-26 | J28: Sin Datos | K28: enzo.fullone@senado.gob.ar | Q28: Bicameral Permanente de la Defensoría del Pueblo | De Agricultura, Ganadería y Pesca | De Infraestructura, Vivienda y Transporte | De Minería, Energía y Combustibles | De Población y Desarrollo Humano | De Sistemas, Medios de Comunicación y Libertad de Expresión | De Turismo | R28: Afirmativo | S28: Afirmativo | U28: Afirmativo | V28: AFIRMATIVO | W28: Afirmativo | X28: AFIRMATIVO | AF28: AFIRMATIVO
A29: =_xlfn.CONCAT(C29," ",B29) | B29: NATALIA ELENA | C29: GADANO | D29: MOVERE SANTA CRUZ | E29: SANTA CRUZ | F29: FUERZA PATRIA | G29: 2019-12-10 | H29: 2031-12-09 | I29: 2019-12-10 | J29: Sin Datos | K29: mariano.recalde@senado.gob.ar | Q29: Banca de la Mujer | De Agricultura, Ganadería y Pesca | De Ambiente y Desarrollo Sustentable | De Defensa Nacional | De Industria y Comercio | De Justicia y Asuntos Penales | De Población y Desarrollo Humano | R29: Afirmativo | S29: Afirmativo | U29: Abstención | V29: NEGATIVO | W29: Afirmativo | X29: AFIRMATIVO | AF29: NEGATIVO
A30: =_xlfn.CONCAT(C30," ",B30) | B30: EDUARDO HORACIO | C30: GALARETTO | D30: UCR - UNIÓN CÍVICA RADICAL | E30: SANTA FE | F30: FUERZA PATRIA | G30: 2025-12-10 | H30: 2031-12-09 | I30: 2025-12-10 | J30: Sin Datos | K30: martin.soria@senado.gob.ar | Q30: Bicameral de Control de los Fondos de la Seguridad Social (Ley 26.425) | De Agricultura, Ganadería y Pesca | De Defensa Nacional | De Deporte | De Economía Nacional e Inversión | De Infraestructura, Vivienda y Transporte | De Minería, Energía y Combustibles | De Salud | De Seguridad Interior y Narcotráfico | R30: Afirmativo | S30: Afirmativo | U30: Afirmativo | V30: AFIRMATIVO | W30: Afirmativo | X30: AFIRMATIVO | AF30: AFIRMATIVO
A31: =_xlfn.CONCAT(C31," ",B31) | B31: MARÍA CELESTE | C31: GIMÉNEZ NAVARRO | D31: JUSTICIALISTA | E31: SAN JUAN | F31: ALIANZA UNIÓN POR LA PATRIA | G31: 2023-12-10 | H31: 2029-12-09 | I31: 2023-12-10 | J31: Sin Datos | K31: eduardo.depedro@senado.gob.ar | L31: 1069 / 1073 / 1080 | M31: https://www.facebook.com/wadodecorrido | N31: https://twitter.com/wadodecorrido | O31: https://www.instagram.com/wadodecorrido | P31: https://www.youtube.com/wadodecorrido | Q31: Bicameral Permanente de Fiscalización de los Órganos y Actividades de Seguridad Interior (Ley 24.059 y Sus Modificatorias Leyes 24.194 y 25.520) | Banca de la Mujer | De Ciencia y Tecnología | De Educación y Cultura | De Legislación General | De Población y Desarrollo Humano | De Salud | De Sistemas, Medios de Comunicación y Libertad de Expresión | R31: Negativo | S31: Negativo | U31: Negativo | V31: NEGATIVO | W31: Negativo | X31: AFIRMATIVO | AF31: NEGATIVO
A32: =_xlfn.CONCAT(C32," ",B32) | B32: JUAN CRUZ | C32: GODOY | D32: LA LIBERTAD AVANZA | E32: CHACO | F32: ALIANZA UNIÓN POR LA PATRIA | G32: 2023-12-10 | H32: 2029-12-09 | I32: 2023-12-10 | J32: Sin Datos | K32: mayans@senado.gob.ar | L32: 1023 / 1036 / 1039 | Q32: Bicameral Permanente de Promoción y Seguimiento de la Comunicación Audiovisual, las Tecnologías de las Telecomunicaciones y la Digitalización (Ley 26.522,Y Sus Modificatorias 27.078 y Dnu 267/15) | Bicameral Permanente de Seguimiento y Control del Ministerio Público de la Nación (Ley 24.946 y Sus Modificatorias Ley 27.148 y 27.149) | De Acuerdos | De Deporte | De Economías Regionales, Economía Social, Micro, Pequeña y Mediana Empresa | De Minería, Energía y Combustibles | De Población y Desarrollo Humano | De Sistemas, Medios de Comunicación y Libertad de Expresión | De Trabajo y Previsión Social | R32: Afirmativo | S32: Afirmativo | U32: Afirmativo | V32: AFIRMATIVO | W32: Afirmativo | X32: AFIRMATIVO | AF32: AFIRMATIVO
A33: =_xlfn.CONCAT(C33," ",B33) | B33: ENRIQUE MARTÍN | C33: GOERLING LARA | D33: FRENTE PRO | E33: MISIONES | F33: FUERZA ENTRE RÍOS | G33: 2025-12-10 | H33: 2031-12-09 | I33: 2025-12-10 | J33: Sin Datos | K33: adan.bahl@senado.gob.ar | Q33: Bicameral Permanente de Fiscalización de los Órganos y Actividades de Seguridad Interior (Ley 24.059 y Sus Modificatorias Leyes 24.194 y 25.520) | Bicameral Permanente de la Defensoría del Pueblo | De Acuerdos | De Agricultura, Ganadería y Pesca | De Ambiente y Desarrollo Sustentable | De Defensa Nacional | De Relaciones Exteriores y Culto | De Seguridad Interior y Narcotráfico | R33: Afirmativo | S33: Afirmativo | U33: Afirmativo | V33: AFIRMATIVO | W33: Afirmativo | X33: AFIRMATIVO | AF33: AFIRMATIVO
A34: =_xlfn.CONCAT(C34," ",B34) | B34: MARÍA TERESA MARGARITA | C34: GONZÁLEZ | D34: JUSTICIALISTA | E34: FORMOSA | F34: ALIANZA UNIÓN POR LA PATRIA | G34: 2023-12-10 | H34: 2029-12-09 | I34: 2023-12-10 | J34: Sin Datos | K34: juliana.ditullio@senado.gob.ar | L34: 1084 / 1098 | Q34: Banca de la Mujer | De Ciencia y Tecnología | De Educación y Cultura | De Infraestructura, Vivienda y Transporte | De Población y Desarrollo Humano | De Salud | R34: Negativo | S34: Negativo | U34: Negativo | V34: NEGATIVO | W34: Negativo | X34: AFIRMATIVO | AF34: NEGATIVO
A35: =_xlfn.CONCAT(C35," ",B35) | B35: GONZALO | C35: GUZMÁN CORAITA | D35: LA LIBERTAD AVANZA | E35: SALTA | F35: FRENTE DE TODOS | G35: 2021-12-10 | H35: 2027-12-09 | I35: 2021-12-10 | J35: Sin Datos | K35: sandra.mendoza@senado.gob.ar | L35: 1477/ 79 / 74 | M35: https://www.facebook.com/sandramentuc | N35: https://twitter.com/sandram_tuc | O35: https://www.instagram.com/sandramendozasn | Q35: De Asuntos Administrativos y Municipales | De Ciencia y Tecnología | De Economía Nacional e Inversión | De Justicia y Asuntos Penales | De Presupuesto y Hacienda | De Relaciones Exteriores y Culto | De Seguridad Interior y Narcotráfico | R35: Afirmativo | S35: Afirmativo | U35: Afirmativo | V35: AFIRMATIVO | W35: Afirmativo | X35: AFIRMATIVO | AF35: AFIRMATIVO
A36: =_xlfn.CONCAT(C36," ",B36) | B36: MARÍA VICTORIA | C36: HUALA | D36: FRENTE PRO | E36: LA PAMPA | F36: PARTIDO RENOVADOR FEDERAL | G36: 2023-12-10 | H36: 2029-12-09 | I36: 2023-12-10 | J36: Sin Datos | K36: vilma.bedia@senado.gob.ar | L36: 3415 | Q36: Bicameral de Control de los Fondos de la Seguridad Social (Ley 26.425) | Bicameral Permanente de Promoción y Seguimiento de la Comunicación Audiovisual, las Tecnologías de las Telecomunicaciones y la Digitalización (Ley 26.522,Y Sus Modificatorias 27.078 y Dnu 267/15) | Banca de la Mujer | De Asuntos Administrativos y Municipales | De Ciencia y Tecnología | De Derechos y Garantías | De Educación y Cultura | De Justicia y Asuntos Penales | De Legislación General | De Población y Desarrollo Humano | De Trabajo y Previsión Social | R36: Afirmativo | S36: Afirmativo | U36: Afirmativo | V36: NEGATIVO | W36: Afirmativo | X36: AFIRMATIVO | AF36: AFIRMATIVO
A37: =_xlfn.CONCAT(C37," ",B37) | B37: LUIS ALFREDO | C37: JUEZ | D37: LA LIBERTAD AVANZA | E37: CÓRDOBA | F37: FRENTE RENOVADOR DE LA CONCORDIA-INNOVACIÓN FEDERAL | G37: 2023-12-10 | H37: 2029-12-09 | I37: 2023-12-10 | J37: Sin Datos | K37: carlos.arce@senado.gob.ar | L37: 1359 / 1364 | Q37: Bicameral Permanente de Seguimiento y Control del Ministerio Público de la Nación (Ley 24.946 y Sus Modificatorias Ley 27.148 y 27.149) | De Asuntos Constitucionales | De Defensa Nacional | De Justicia y Asuntos Penales | De Legislación General | De Relaciones Exteriores y Culto | R37: Afirmativo | S37: Afirmativo | U37: Afirmativo | V37: AFIRMATIVO | W37: Afirmativo | X37: AFIRMATIVO | AF37: AUSENTE
A38: =_xlfn.CONCAT(C38," ",B38) | B38: MARIANA | C38: JURI | D38: UCR - UNIÓN CÍVICA RADICAL | E38: MENDOZA | F38: FRENTE CAMBIA MENDOZA | G38: 2023-12-09 | H38: 2027-12-09 | I38: 2023-12-09 | J38: Sin Datos | K38: rodolfo.suarez@senado.gob.ar | L38: 1460 | M38: https://www.facebook.com/RodolfoSuarezMendoza | N38: https://twitter.com/rodysuarez | O38: https://www.instagram.com/rody.suarez | Q38: Banca de la Mujer | De Ciencia y Tecnología | De Deporte | De Economía Nacional e Inversión | De Infraestructura, Vivienda y Transporte | De Minería, Energía y Combustibles | R38: Afirmativo | S38: Afirmativo | U38: Afirmativo | V38: AFIRMATIVO | W38: Afirmativo | X38: AFIRMATIVO | AF38: AFIRMATIVO
A39: =_xlfn.CONCAT(C39," ",B39) | B39: ALICIA MARGARITA ANTONIA | C39: KIRCHNER | D39: JUSTICIALISTA | E39: SANTA CRUZ | F39: FRENTE TODOS | G39: 2021-12-10 | H39: 2027-12-09 | I39: 2021-12-10 | J39: Sin Datos | K39: carlos.espinola@senado.gob.ar | L39: 1222 / 1225 / 3183 / 3190 | N39: https://twitter.com/espinolacamau | Q39: Bicameral Permanente de la Defensoría del Pueblo | Bicameral Permanente de Seguimiento y Control del Ministerio Público de la Nación (Ley 24.946 y Sus Modificatorias Ley 27.148 y 27.149) | Banca de la Mujer | De Coparticipación Federal de Impuestos | De Derechos y Garantías | De Legislación General | De Población y Desarrollo Humano | De Turismo | R39: Negativo | S39: Negativo | U39: Negativo | V39: NEGATIVO | W39: Negativo | X39: AFIRMATIVO | AF39: NEGATIVO
A40: =_xlfn.CONCAT(C40," ",B40) | B40: DANIEL RICARDO | C40: KRONEBERGER | D40: UCR - UNIÓN CÍVICA RADICAL | E40: LA PAMPA | F40: JUNTOS POR EL CAMBIO CHUBUT | G40: 2021-12-10 | H40: 2027-12-09 | I40: 2021-12-10 | J40: Sin Datos | K40: edith.terenzi@senado.gob.ar | L40: 3538 | Q40: Bicameral Permanente de la Defensoría del Pueblo | De Agricultura, Ganadería y Pesca | De Ambiente y Desarrollo Sustentable | De Asuntos Administrativos y Municipales | De Economía Nacional e Inversión | De Economías Regionales, Economía Social, Micro, Pequeña y Mediana Empresa | De Industria y Comercio | De Población y Desarrollo Humano | De Sistemas, Medios de Comunicación y Libertad de Expresión | R40: Negativo | S40: Afirmativo | U40: Afirmativo | V40: NEGATIVO | W40: Afirmativo | X40: AFIRMATIVO | AF40: AFIRMATIVO
...

Sheet APOYO
A2: BLOQUE
A3: UCR - UNIÓN CÍVICA RADICAL | B3: =COUNTIF(Senado!D:D,APOYO!A3)
A4: LA LIBERTAD AVANZA | B4: =COUNTIF(Senado!D:D,APOYO!A4)
A5: CONVICCIÓN FEDERAL | B5: =COUNTIF(Senado!D:D,APOYO!A5)
A6: FRENTE RENOVADOR DE LA CONCORDIA SOCIAL | B6: =COUNTIF(Senado!D:D,APOYO!A6)
A7: INDEPENDENCIA | B7: =COUNTIF(Senado!D:D,APOYO!A7)
A8: JUSTICIALISTA | B8: =COUNTIF(Senado!D:D,APOYO!A8)
A9: MOVERE POR SANTA CRUZ | B9: =COUNTIF(Senado!D:D,APOYO!A9)
A10: LA NEUQUINIDAD | B10: =COUNTIF(Senado!D:D,APOYO!A10)
A11: FRENTE PRO | B11: =COUNTIF(Senado!D:D,APOYO!A11)
A12: PROVINCIAS UNIDAS | B12: =COUNTIF(Senado!D:D,APOYO!A12)
A13: PRIMERO LOS SALTEÑOS | B13: =COUNTIF(Senado!D:D,APOYO!A13)
A14: DESPIERTA CHUBUT | B14: =COUNTIF(Senado!D:D,APOYO!A14)
